Workbook

Sheet Feuil1
A1: Nom | B1: Prénom | E1: Nom | F1: Prénom | I1: Nom | J1: Prénom
A2: Rodrigues | B2: Estellie | C2: x | E2: Zemihi | F2: Illan | I2: Baptiste | J2: Valéry
A3: Szulc Bapiska | B3: Jean | E3: Zemihi | F3: Enzo | I3: Delaurent | J3: Léonard
A4: Jarry | B4: Hugo | C4: x | E4: Rodrigues | F4: Estellie | I4: Dieny | J4: Victor
A5: Dieny | B5: Victor | C5: x | E5: Szulc Bapiski | F5: Jean | I5: Fiorina | J5: Maelys
A6: Delaurent | B6: Léonard | E6: Sarry | F6: Hugo | I6: Gerot | J6: Gabriel
A7: Baptiste | B7: Valéry | E7: Dieny | F7: Victor | I7: Henry | J7: Mathis
A8: Henry | B8: Mathis | E8: Delaurent | F8: Léonard | I8: Herouard | J8: Maud
A9: Schuurman | B9: Solveig | E9: Baptiste | F9: Valéry | I9: Jiaque | J9: Huang
A10: Nolot | B10: Lia | E10: Henry | F10: Mathis | I10: Kadik | J10: Sostène
A11: Wong | B11: Po-Chun | E11: Schuurman | F11: Tolberg | I11: Lhomite | J11: Anaïs
A12: Ozenne | B12: Henri | E12: Nolot | F12: Lia | I12: Makkpafi | J12: Olivia
A13: Kadik | B13: Sostène | E13: Wong | F13: Po-Chun | I13: Nolot | J13: Léa
A14: Plait | B14: Mélodie | E14: Ozenne | F14: Henri | I14: Nolot | J14: Lia
A15: Vieuvormain | B15: Héloïse | E15: Kadik | F15: Sostène | I15: Ozenne | J15: Henri
E16: Plait | F16: Mélodie | I16: Plait | J16: Mélodie
E17: Vieuvormain | F17: Héloïse | I17: Protois | J17: Nathanaël
I18: Rodrigues | J18: Estellie
I19: Sarry | J19: Hugo
I20: Schuurman | J20: Tolberg
I21: Szulc Bapiski | J21: Jean
I22: Velon | J22: Blie
I23: Vieuvormain | J23: Héloïse
I24: Wong | J24: Po-Chun

Sheet Inscrit à la discipline
A1: extraction produite de | B1: https://ent.cnsmdp.fr/#name=COURSE&type=DETAIL&code=003481&VERSION=PROD&mainTab=COURSEetudiants
A3: [[ LNAME_CIVIL ]] | B3: [[ FNAME ]] | C3: [[ CODE ]]
A4: Nom de naissance | B4: Prénom d'usage | C4: Identifiant Oasis | D4: Statut | E4: Mention | F4: Appréciations (Visibles par l'étudiant) | G4: Absences
A5: Agondjo Ndenguinot | B5: Pierre Louis | C5: plagondjondenguinot | G5: =COUNTIF(Absents!F:F,'Inscrit à la discipline'!C5) -> 0
A6: Aguerre | B6: Tristan | C6: taguerre | G6: =COUNTIF(Absents!F:F,'Inscrit à la discipline'!C6) -> 0
A7: Amano | B7: Yui | C7: yamano | G7: =COUNTIF(Absents!F:F,'Inscrit à la discipline'!C7) -> 0
A8: Amir-Tahmasseb | B8: Vincent | C8: vamirtahmasseb | G8: =COUNTIF(Absents!F:F,'Inscrit à la discipline'!C8) -> 0
A9: Angloma | B9: Noam, Sofiane, Milo | C9: nsmangloma | G9: =COUNTIF(Absents!F:F,'Inscrit à la discipline'!C9) -> 0
A10: Angot | B10: Mélissa | C10: mangot | G10: =COUNTIF(Absents!F:F,'Inscrit à la discipline'!C10) -> 0
A11: Archimbaud--Adad | B11: Solal | C11: sarchimbaudadad | G11: =COUNTIF(Absents!F:F,'Inscrit à la discipline'!C11) -> 0
A12: Athane | B12: Madeleine | C12: mathanebest | F12: APM1 - VALIDE via son DNSPM | G12: =COUNTIF(Absents!F:F,'Inscrit à la discipline'!C12) -> 0
A13: Aubry | B13: Timothée | C13: taubry1 | G13: =COUNTIF(Absents!F:F,'Inscrit à la discipline'!C13) -> 0
A14: Baltardive | B14: Garance | C14: gbaltardive | G14: =COUNTIF(Absents!F:F,'Inscrit à la discipline'!C14) -> 0
A15: Barret--Fontealba | B15: Juliette | C15: jbarretfontealba | G15: =COUNTIF(Absents!F:F,'Inscrit à la discipline'!C15) -> 0
A16: Batogé | B16: Jean-Baptiste | C16: jbbatoge | G16: =COUNTIF(Absents!F:F,'Inscrit à la discipline'!C16) -> 0
A17: Belon | B17: Lucas | C17: lbelon | G17: =COUNTIF(Absents!F:F,'Inscrit à la discipline'!C17) -> 0
A18: Berson | B18: Antonin | C18: aberson | G18: =COUNTIF(Absents!F:F,'Inscrit à la discipline'!C18) -> 0
A19: Bianchi | B19: Manuela | C19: mbianchi | G19: =COUNTIF(Absents!F:F,'Inscrit à la discipline'!C19) -> 0
A20: Bich | B20: Alphonse | C20: abich | G20: =COUNTIF(Absents!F:F,'Inscrit à la discipline'!C20) -> 0
A21: Bischoff | B21: Louis | C21: lbischoff1 | G21: =COUNTIF(Absents!F:F,'Inscrit à la discipline'!C21) -> 0
A22: Blouet | B22: Martin | C22: mblouet | G22: =COUNTIF(Absents!F:F,'Inscrit à la discipline'!C22) -> 0
A23: Bomont | B23: Albert | C23: abomont | G23: =COUNTIF(Absents!F:F,'Inscrit à la discipline'!C23) -> 0
A24: Bondet de la Bernardie | B24: Derek | C24: dbondetdelabernardie | G24: =COUNTIF(Absents!F:F,'Inscrit à la discipline'!C24) -> 0
... A29: Carde | B29: Anaïs | C29: acarde | G29: =COUNTIF(Absents!F:F,'Inscrit à la discipline'!C29) -> 0
A30: Caron | B30: Etienne | C30: ecaron | F30: APM 1& 2 Déjà validé en 22-23. | G30: =COUNTIF(Absents!F:F,'Inscrit à la discipline'!C30) -> 0
A31: Casati--Lewandowski | B31: Fanny | C31: fcasatilewandowski | G31: =COUNTIF(Absents!F:F,'Inscrit à la discipline'!C31) -> 0
A32: Cé | B32: Jean | C32: jce | G32: =COUNTIF(Absents!F:F,'Inscrit à la discipline'!C32) -> 0
A33: Charles | B33: Jonas | C33: jcharles2 | G33: =COUNTIF(Absents!F:F,'Inscrit à la discipline'!C33) -> 0
A34: Chauvet | B34: Victor | C34: vchauvet | G34: =COUNTIF(Absents!F:F,'Inscrit à la discipline'!C34) -> 0
A35: Chavanon | B35: Louise | C35: lchavanon | G35: =COUNTIF(Absents!F:F,'Inscrit à la discipline'!C35) -> 0
A36: Choisi | B36: Dylan | C36: dchoisi | G36: =COUNTIF(Absents!F:F,'Inscrit à la discipline'!C36) -> 0
A37: Christophe | B37: Antonin | C37: achristophe1 | G37: =COUNTIF(Absents!F:F,'Inscrit à la discipline'!C37) -> 0
A38: Cohen | B38: Shaïna | C38: scohen | G38: =COUNTIF(Absents!F:F,'Inscrit à la discipline'!C38) -> 0
A39: Cohen-Akenine | B39: Raphaël | C39: rcohenakenine | G39: =COUNTIF(Absents!F:F,'Inscrit à la discipline'!C39) -> 0
A40: Conesa | B40: Virgile | C40: vconesa | G40: =COUNTIF(Absents!F:F,'Inscrit à la discipline'!C40) -> 0
A41: Constable | B41: Elisa | C41: econstable | G41: =COUNTIF(Absents!F:F,'Inscrit à la discipline'!C41) -> 0
A42: Coppola | B42: Christiana | C42: ccoppola | G42: =COUNTIF(Absents!F:F,'Inscrit à la discipline'!C42) -> 0
... A49: Delhoume | B49: Antoine | C49: adelhoume | G49: =COUNTIF(Absents!F:F,'Inscrit à la discipline'!C49) -> 0
A50: Deschodt | B50: Florian | C50: fdeschodt | D50: Validé | F50: APM 1 Valid via son DNSPM | G50: =COUNTIF(Absents!F:F,'Inscrit à la discipline'!C50) -> 0
A51: Dieny | B51: Victor | C51: vdieny | G51: =COUNTIF(Absents!F:F,'Inscrit à la discipline'!C51) -> 0
...

Sheet Absents
A1: Extraction obtenue par | C1: https://ent.cnsmdp.fr/#type=LIST&name=DEFECTION&operator=and&page=1&CODE_SESSION=102753_OU_102916_OU_104550_OU_104551_OU_104820_OU_104855_OU_104959
A3: [[ TYPE ]] | B3: [[ CODE_STUDENT ]] | C3: [[ CODE_SESSION ]] | D3: [[ DATETIME_START ]] | E3: [[ DATETIME_END ]] | F3: [[ CODE ]]
A4: Type | B4: Étudiant | C4: Séance | D4: Début | E4: Fin | F4: Identifiant Oasis
A5: Absence | B5: Minghetti Léo | C5: 003481 - Parcours Pro A - Santé et prévention (ex-APM1) (Cours magistral) | D5: 45908.375 | E5: 45908.438 | F5: lminghetti
A6: Absence | B6: Vandenhole Louise | C6: 003481 - Parcours Pro A - Santé et prévention (ex-APM1) (Cours magistral) | D6: 45908.375 | E6: 45908.438 | F6: lvandenhole
A7: Absence | B7: Minghetti Léo | C7: 003481 - Parcours Pro A - Santé et prévention (ex-APM1) (Cours magistral) | D7: 45909.396 | E7: 45909.479 | F7: lminghetti
A8: Absence | B8: Vandenhole Louise | C8: 003481 - Parcours Pro A - Santé et prévention (ex-APM1) (Cours magistral) | D8: 45909.396 | E8: 45909.479 | F8: lvandenhole
A9: Absence | B9: Marchès--Saury Milo | C9: 003481 - Parcours Pro A - Santé et prévention (ex-APM1) (Cours magistral) | D9: 45909.396 | E9: 45909.479 | F9: mmarchessaury

Sheet OASIS
A1: Discipline | B1: Etudiant | C1: Mention | D1: Status | E1: Commentaire pour OASIS
A2: 003481 | B2: nokuda | C2: AB | D2: VALIDATE | E2: lmklmdsklmfd
A3: 003481 | B3: garaujodealmeida | C3: B | D3: VALIDATE | E3: fdlsmkfds
A4: 003481 | B4: skawai | C4: B | D4: VALIDATE | E4: test B
A5: 003481 | B5: sshin | C5: B | D5: VALIDATE | E5: fdlsmkfds
A6: 003481 | B6: tsuzuki | C6: B | D6: VALIDATE | E6: test B
A7: 003481 | B7: acantonnet | C7: B | D7: VALIDATE | E7: fdlsmkfds
A8: 003481 | B8: clee | C8: B | D8: VALIDATE | E8: test B
A9: 003481 | B9: ldepoli | C9: B | D9: VALIDATE | E9: fdlsmkfds
A10: 003481 | B10: schauvire | C10: B | D10: VALIDATE | E10: test B
A11: 003481 | B11: wtechin | C11: B | D11: VALIDATE | E11: fdlsmkfds
A12: 003481 | B12: acesari | C12: B | D12: VALIDATE | E12: test B
... A29: 003481 | B29: gsardier | C29: B | D29: VALIDATE | E29: fdlsmkfds
