Workbook

Sheet 003481
A1: Ligne | B1: Date | C1: Date | D1: Heure de début | E1: Heure de fin | F1: Type d'émargement | G1: Statut de l'émargement | H1: Étudiant | I1: Étudiant - PréNom | J1: Séance | K1: Étudiant - Nom | L1: Statut de l'étudiant | M1: Nom prenom | N1: commentaire | Q1: Doublon
A2: 1 | C2: 45909 | D2: 0.39583333 | E2: 0.47916667 | F2: QR Code | G2: Émargée | H2: plagondjondenguinot | I2: Pierre Louis | J2: 104959 | K2: Agondjo Ndenguinot | L2: PRESENCE | M2: =I2 & " " & K2 -> Pierre Louis Agondjo Ndenguinot | Q2: =J2&H2 -> 104959plagondjondenguinot
A3: 3 | C3: 45908 | D3: 0.58333333 | E3: 0.64583333 | F3: QR Code | G3: Émargée | H3: plagondjondenguinot | I3: Pierre Louis | J3: 104551 | K3: Agondjo Ndenguinot | L3: PRESENCE | M3: =I3 & " " & K3 -> Pierre Louis Agondjo Ndenguinot | Q3: =J3&H3 -> 104551plagondjondenguinot
A4: 4 | C4: 45908 | D4: 0.47916667 | E4: 0.54166667 | F4: QR Code | G4: Émargée | H4: plagondjondenguinot | I4: Pierre Louis | J4: 104550 | K4: Agondjo Ndenguinot | L4: PRESENCE | M4: =I4 & " " & K4 -> Pierre Louis Agondjo Ndenguinot | Q4: =J4&H4 -> 104550plagondjondenguinot
A5: 5 | C5: 45908 | D5: 0.375 | E5: 0.4375 | F5: QR Code | G5: Émargée | H5: plagondjondenguinot | I5: Pierre Louis | J5: 102916 | K5: Agondjo Ndenguinot | L5: PRESENCE | M5: =K5 & " " & I5 -> Agondjo Ndenguinot Pierre Louis | Q5: =J5&H5 -> 102916plagondjondenguinot
A6: 6 | C6: 45909 | D6: 0.39583333 | E6: 0.47916667 | F6: QR Code | G6: Émargée | H6: taguerre | I6: b | J6: 104959 | K6: Aguerre | L6: PRESENCE | M6: =I6 & " " & K6 -> b Aguerre | Q6: =J6&H6 -> 104959taguerre
A7: 7 | C7: 45909 | D7: 0.39583333 | E7: 0.47916667 | F7: QR Code | G7: Émargée | H7: yamano | I7: Yui | J7: 104959 | K7: Amano | L7: PRESENCE | M7: =I7 & " " & K7 -> Yui Amano | Q7: =J7&H7 -> 104959yamano
A8: 8 | C8: 45908 | D8: 0.66666667 | E8: 0.72916667 | F8: QR Code | G8: Émargée | H8: taguerre | I8: Tristan | J8: 104855 | K8: Aguerre | L8: PRESENCE | M8: =I8 & " " & K8 -> Tristan Aguerre | Q8: =J8&H8 -> 104855taguerre
A9: 10 | C9: 45908 | D9: 0.58333333 | E9: 0.64583333 | F9: QR Code | G9: Émargée | H9: taguerre | I9: Tristan | J9: 104551 | K9: Aguerre | L9: PRESENCE | M9: =I9 & " " & K9 -> Tristan Aguerre | Q9: =J9&H9 -> 104551taguerre
A10: 11 | C10: 45908 | D10: 0.47916667 | E10: 0.54166667 | F10: QR Code | G10: Émargée | H10: taguerre | I10: Tristan | J10: 104550 | K10: Aguerre | L10: PRESENCE | M10: =I10 & " " & K10 -> Tristan Aguerre | Q10: =J10&H10 -> 104550taguerre
A11: 12 | C11: 45908 | D11: 0.375 | E11: 0.4375 | F11: QR Code | G11: Émargée | H11: taguerre | I11: Tristan | J11: 102916 | K11: Aguerre | L11: PRESENCE | M11: =I11 & " " & K11 -> Tristan Aguerre | Q11: =J11&H11 -> 102916taguerre
A12: 13 | C12: 45909 | D12: 0.39583333 | E12: 0.47916667 | F12: QR Code | G12: Émargée | H12: vamirtahmasseb | I12: Vincent | J12: 104959 | K12: Amir-Tahmasseb | L12: PRESENCE | M12: =I12 & " " & K12 -> Vincent Amir-Tahmasseb | Q12: =J12&H12 -> 104959vamirtahmasseb
A13: 14 | C13: 45909 | D13: 0.39583333 | E13: 0.47916667 | F13: QR Code | G13: Émargée | H13: nsmangloma | I13: Noam, Sofiane, Milo | J13: 104959 | K13: Angloma | L13: ABSENCE | M13: =K13 & " " & I13 -> Angloma Noam, Sofiane, Milo | Q13: =J13&H13 -> 104959nsmangloma
A14: 15 | C14: 45908 | D14: 0.66666667 | E14: 0.72916667 | F14: QR Code | G14: Émargée | H14: yamano | I14: Yui | J14: 104855 | K14: Amano | L14: PRESENCE | M14: =I14 & " " & K14 -> Yui Amano | Q14: =J14&H14 -> 104855yamano
A15: 18 | C15: 45908 | D15: 0.58333333 | E15: 0.64583333 | F15: QR Code | G15: Émargée | H15: yamano | I15: Yui | J15: 104551 | K15: Amano | L15: PRESENCE | M15: =I15 & " " & K15 -> Yui Amano | Q15: =J15&H15 -> 104551yamano
A16: 19 | C16: 45908 | D16: 0.47916667 | E16: 0.54166667 | F16: QR Code | G16: Émargée | H16: yamano | I16: Yui | J16: 104550 | K16: Amano | L16: PRESENCE | M16: =I16 & " " & K16 -> Yui Amano | Q16: =J16&H16 -> 104550yamano
A17: 20 | C17: 45908 | D17: 0.375 | E17: 0.4375 | F17: QR Code | G17: Émargée | H17: yamano | I17: Yui | J17: 102916 | K17: Amano | L17: PRESENCE | M17: =I17 & " " & K17 -> Yui Amano | Q17: =J17&H17 -> 102916yamano
A18: 21 | C18: 45909 | D18: 0.39583333 | E18: 0.47916667 | F18: QR Code | G18: Émargée | H18: mangot | I18: Mélissa | J18: 104959 | K18: Angot | L18: PRESENCE | M18: =I18 & " " & K18 -> Mélissa Angot | Q18: =J18&H18 -> 104959mangot
A19: 22 | C19: 45909 | D19: 0.39583333 | E19: 0.47916667 | F19: QR Code | G19: Émargée | H19: sarchimbaudadad | I19: Solal | J19: 104959 | K19: Archimbaud--Adad | L19: PRESENCE | M19: =I19 & " " & K19 -> Solal Archimbaud--Adad | Q19: =J19&H19 -> 104959sarchimbaudadad
A20: 23 | C20: 45908 | D20: 0.66666667 | E20: 0.72916667 | F20: QR Code | G20: Émargée | H20: vamirtahmasseb | I20: Vincent | J20: 104855 | K20: Amir-Tahmasseb | L20: PRESENCE | M20: =I20 & " " & K20 -> Vincent Amir-Tahmasseb | Q20: =J20&H20 -> 104855vamirtahmasseb
A21: 26 | C21: 45908 | D21: 0.58333333 | E21: 0.64583333 | F21: QR Code | G21: Émargée | H21: vamirtahmasseb | I21: Vincent | J21: 104551 | K21: Amir-Tahmasseb | L21: PRESENCE | M21: =I21 & " " & K21 -> Vincent Amir-Tahmasseb | Q21: =J21&H21 -> 104551vamirtahmasseb
A22: 27 | C22: 45908 | D22: 0.47916667 | E22: 0.54166667 | F22: QR Code | G22: Émargée | H22: vamirtahmasseb | I22: Vincent | J22: 104550 | K22: Amir-Tahmasseb | L22: PRESENCE | M22: =I22 & " " & K22 -> Vincent Amir-Tahmasseb | Q22: =J22&H22 -> 104550vamirtahmasseb
A23: 28 | C23: 45908 | D23: 0.375 | E23: 0.4375 | F23: QR Code | G23: Émargée | H23: vamirtahmasseb | I23: Vincent | J23: 102916 | K23: Amir-Tahmasseb | L23: PRESENCE | M23: =I23 & " " & K23 -> Vincent Amir-Tahmasseb | Q23: =J23&H23 -> 102916vamirtahmasseb
A24: 29 | C24: 45909 | D24: 0.39583333 | E24: 0.47916667 | F24: QR Code | G24: Émargée | H24: mathanebest | I24: Madeleine | J24: 104959 | K24: Athané-Best | L24: ABSENCE | M24: =K24 & " " & I24 -> Athané-Best Madeleine | Q24: =J24&H24 -> 104959mathanebest
A25: 30 | C25: 45909 | D25: 0.39583333 | E25: 0.47916667 | F25: QR Code | G25: Émargée | H25: taubry1 | I25: Timothée | J25: 104959 | K25: Aubry | L25: PRESENCE | M25: =I25 & " " & K25 -> Timothée Aubry | Q25: =J25&H25 -> 104959taubry1
A26: 31 | C26: 45908 | D26: 0.66666667 | E26: 0.72916667 | F26: QR Code | G26: Émargée | H26: nsmangloma | I26: Noam, Sofiane, Milo | J26: 104855 | K26: Angloma | L26: PRESENCE | M26: =I26 & " " & K26 -> Noam, Sofiane, Milo Angloma | Q26: =J26&H26 -> 104855nsmangloma
A27: 33 | C27: 45908 | D27: 0.58333333 | E27: 0.64583333 | F27: QR Code | G27: Émargée | H27: nsmangloma | I27: Noam, Sofiane, Milo | J27: 104551 | K27: Angloma | L27: PRESENCE | M27: =I27 & " " & K27 -> Noam, Sofiane, Milo Angloma | Q27: =J27&H27 -> 104551nsmangloma
A28: 34 | C28: 45908 | D28: 0.47916667 | E28: 0.54166667 | F28: QR Code | G28: Émargée | H28: nsmangloma | I28: Noam, Sofiane, Milo | J28: 104550 | K28: Angloma | L28: PRESENCE | M28: =I28 & " " & K28 -> Noam, Sofiane, Milo Angloma | Q28: =J28&H28 -> 104550nsmangloma
A29: 35 | C29: 45908 | D29: 0.375 | E29: 0.4375 | F29: QR Code | G29: Émargée | H29: nsmangloma | I29: Noam, Sofiane, Milo | J29: 102916 | K29: Angloma | L29: PRESENCE | M29: =I29 & " " & K29 -> Noam, Sofiane, Milo Angloma | Q29: =J29&H29 -> 102916nsmangloma
A30: 36 | C30: 45909 | D30: 0.39583333 | E30: 0.47916667 | F30: QR Code | G30: Émargée | H30: gbaltardive | I30: Garance | J30: 104959 | K30: Baltardive | L30: PRESENCE | M30: =I30 & " " & K30 -> Garance Baltardive | Q30: =J30&H30 -> 104959gbaltardive
A31: 37 | C31: 45909 | D31: 0.39583333 | E31: 0.47916667 | F31: QR Code | G31: Émargée | H31: jbarretfontealba | I31: Juliette | J31: 104959 | K31: Barret--Fontealba | L31: PRESENCE | M31: =I31 & " " & K31 -> Juliette Barret--Fontealba | Q31: =J31&H31 -> 104959jbarretfontealba
A32: 38 | C32: 45908 | D32: 0.66666667 | E32: 0.72916667 | F32: QR Code | G32: Émargée | H32: mangot | I32: Mélissa | J32: 104855 | K32: Angot | L32: PRESENCE | M32: =I32 & " " & K32 -> Mélissa Angot | Q32: =J32&H32 -> 104855mangot
A33: 40 | C33: 45908 | D33: 0.58333333 | E33: 0.64583333 | F33: QR Code | G33: Émargée | H33: mangot | I33: Mélissa | J33: 104551 | K33: Angot | L33: PRESENCE | M33: =I33 & " " & K33 -> Mélissa Angot | Q33: =J33&H33 -> 104551mangot
A34: 41 | C34: 45908 | D34: 0.47916667 | E34: 0.54166667 | F34: QR Code | G34: Émargée | H34: mangot | I34: Mélissa | J34: 104550 | K34: Angot | L34: PRESENCE | M34: =I34 & " " & K34 -> Mélissa Angot | Q34: =J34&H34 -> 104550mangot
A35: 42 | C35: 45908 | D35: 0.375 | E35: 0.4375 | F35: QR Code | G35: Émargée | H35: mangot | I35: Mélissa | J35: 102916 | K35: Angot | L35: PRESENCE | M35: =I35 & " " & K35 -> Mélissa Angot | Q35: =J35&H35 -> 102916mangot
A36: 43 | C36: 45909 | D36: 0.39583333 | E36: 0.47916667 | F36: QR Code | G36: Émargée | H36: jbbatoge | I36: Jean-Baptiste | J36: 104959 | K36: Batogé | L36: PRESENCE | M36: =I36 & " " & K36 -> Jean-Baptiste Batogé | Q36: =J36&H36 -> 104959jbbatoge
... A43: 51 | C43: 45909 | D43: 0.39583333 | E43: 0.47916667 | F43: QR Code | G43: Émargée | H43: mbianchi | I43: Manuela | J43: 104959 | K43: Bianchi | L43: PRESENCE | M43: =I43 & " " & K43 -> Manuela Bianchi | Q43: =J43&H43 -> 104959mbianchi
A44: 52 | C44: 45908 | D44: 0.66666667 | E44: 0.72916667 | F44: QR Code | G44: Émargée | H44: mathanebest | I44: Madeleine | J44: 104855 | K44: Athané-Best | L44: ABSENCE | M44: =K44 & " " & I44 -> Athané-Best Madeleine | Q44: =J44&H44 -> 104855mathanebest
A45: 54 | C45: 45908 | D45: 0.58333333 | E45: 0.64583333 | F45: QR Code | G45: Émargée | H45: mathanebest | I45: Madeleine | J45: 104551 | K45: Athané-Best | L45: ABSENCE | M45: =K45 & " " & I45 -> Athané-Best Madeleine | Q45: =J45&H45 -> 104551mathanebest
A46: 55 | C46: 45908 | D46: 0.47916667 | E46: 0.54166667 | F46: QR Code | G46: Émargée | H46: mathanebest | I46: Madeleine | J46: 104550 | K46: Athané-Best | L46: ABSENCE | M46: =K46 & " " & I46 -> Athané-Best Madeleine | Q46: =J46&H46 -> 104550mathanebest
...

Sheet OASIS
A1: Discipline | B1: Etudiant | C1: Mention | D1: Status | E1: Commentaire
A2: 003481 | B2: =IF(Synthese!O38,Synthese!G38,"") -> aberson | D2: =IF(B2<>"","VALIDATE","") -> VALIDATE
A3: 003481 | B3: =IF(Synthese!O39,Synthese!G39,"") -> abich | D3: =IF(B3<>"","VALIDATE","") -> VALIDATE
A4: 003481 | B4: =IF(Synthese!O40,Synthese!G40,"") | D4: =IF(B4<>"","VALIDATE","")
A5: 003481 | B5: =IF(Synthese!O41,Synthese!G41,"") -> acarde | D5: =IF(B5<>"","VALIDATE","") -> VALIDATE
A6: 003481 | B6: =IF(Synthese!O42,Synthese!G42,"") -> achristophe1 | D6: =IF(B6<>"","VALIDATE","") -> VALIDATE
A7: 003481 | B7: =IF(Synthese!O43,Synthese!G43,"") -> adecaens | D7: =IF(B7<>"","VALIDATE","") -> VALIDATE
A8: 003481 | B8: =IF(Synthese!O44,Synthese!G44,"") -> adelhoume | D8: =IF(B8<>"","VALIDATE","") -> VALIDATE
A9: 003481 | B9: =IF(Synthese!O45,Synthese!G45,"") -> adorlandepolignac | D9: =IF(B9<>"","VALIDATE","") -> VALIDATE
A10: 003481 | B10: =IF(Synthese!O46,Synthese!G46,"") -> aeorthmannreichenbach | D10: =IF(B10<>"","VALIDATE","") -> VALIDATE
A11: 003481 | B11: =IF(Synthese!O47,Synthese!G47,"") -> aesmaeilzadeh | D11: =IF(B11<>"","VALIDATE","") -> VALIDATE
A12: 003481 | B12: =IF(Synthese!O48,Synthese!G48,"") | D12: =IF(B12<>"","VALIDATE","")
A13: 003481 | B13: =IF(Synthese!O49,Synthese!G49,"") | D13: =IF(B13<>"","VALIDATE","")
... A251: 003481 | B251: =IF(Synthese!O287,Synthese!G287,"") -> zlyu | D251: =IF(B251<>"","VALIDATE","") -> VALIDATE

Sheet Synthese
G4: Nombre de Étudiant | H4: Statut de l'étudiant
G5: Séance | H5: ABSENCE | I5: PRESENCE | J5: (vide) | K5: Total général
G6: 102753 | H6: 64 | I6: 147 | K6: 211 | O6: a vérifier avec les feuilles d'émargement
G7: 102916 | H7: 68 | I7: 150 | K7: 218
G8: 104550 | H8: 65 | I8: 166 | K8: 231
G9: 104551 | H9: 59 | I9: 170 | K9: 229 | O9: a recopier a partir de la séance de 9h
G10: 104855 | H10: 48 | I10: 158 | K10: 206
G11: 104959 | H11: 68 | I11: 174 | K11: 242
G12: (vide)
H14: =AVERAGE(H6:H11) -> 62 | I14: =AVERAGE(I6:I11) -> 160.83333
G35: Nombre de Séance | I35: Statut de l'étudiant | O35: Aurais validé | P35: Ne valide pas
G36: Étudiant | H36: Étudiant - Nom | I36: ABSENCE | J36: PRESENCE | K36: (vide) | L36: Total général | N36: =SUM(N37:N289) -> 211 | O36: =SUM(O37:O289) -> 145 | R36: Nombre de Étudiant
G37: a | H37: (vide) | J37: 1 | L37: 1 | N37: =IF(L37>4,1,0) -> 0 | O37: =IF(AND(I37>1,I37<5),G37,"") | P37: =IF(OR(ISBLANK(J37),J37<5),G37,"") -> a | R37: Séance | S37: Heures (Heure de fin) | T37: Heure de début | U37: Heure de fin | V37: Total
G38: aberson | H38: Berson | J38: 6 | L38: 6 | N38: =IF(L38>4,1,0) -> 1 | O38: =IF(J38>4,1,0) -> 1 | P38: =IF(OR(ISBLANK(J38),J38<5),G38,"") | R38: 102753 | S38: 13 | V38: 211
G39: abich | H39: Bich | I39: 1 | J39: 5 | L39: 6 | N39: =IF(L39>4,1,0) -> 1 | O39: =IF(J39>4,1,0) -> 1 | P39: =IF(OR(ISBLANK(J39),J39<5),G39,"") | R39: 102916 | S39: 10 | V39: 217
G40: abomont | H40: Bomont | I40: 6 | L40: 6 | N40: =IF(L40>4,1,0) -> 1 | O40: =IF(J40>4,1,0) -> 0 | P40: =IF(OR(ISBLANK(J40),J40<5),G40,"") -> abomont | S40: 13 | V40: 1
G41: acarde | H41: Carde | J41: 6 | L41: 6 | N41: =IF(L41>4,1,0) -> 1 | O41: =IF(J41>4,1,0) -> 1 | P41: =IF(OR(ISBLANK(J41),J41<5),G41,"") | R41: 104550 | S41: <00/01/1900 | V41: 18
G42: achristophe1 | H42: Christophe | J42: 6 | L42: 6 | N42: =IF(L42>4,1,0) -> 1 | O42: =IF(J42>4,1,0) -> 1 | P42: =IF(OR(ISBLANK(J42),J42<5),G42,"") | S42: 10 | V42: 1
G43: adecaens | H43: Decaëns | J43: 6 | L43: 6 | N43: =IF(L43>4,1,0) -> 1 | O43: =IF(J43>4,1,0) -> 1 | P43: =IF(OR(ISBLANK(J43),J43<5),G43,"") | S43: 13 | V43: 212
G44: adelhoume | H44: Delhoume | J44: 6 | L44: 6 | N44: =IF(L44>4,1,0) -> 1 | O44: =IF(J44>4,1,0) -> 1 | P44: =IF(OR(ISBLANK(J44),J44<5),G44,"") | R44: 104551 | S44: <00/01/1900 | V44: 18
G45: adorlandepolignac | H45: d'Orlan de Polignac | J45: 6 | L45: 6 | N45: =IF(L45>4,1,0) -> 1 | O45: =IF(J45>4,1,0) -> 1 | P45: =IF(OR(ISBLANK(J45),J45<5),G45,"") | S45: 15 | V45: 211
G46: aeorthmannreichenbach | H46: Orthmann--Reichenbach | I46: 1 | J46: 5 | L46: 6 | N46: =IF(L46>4,1,0) -> 1 | O46: =IF(J46>4,1,0) -> 1 | P46: =IF(OR(ISBLANK(J46),J46<5),G46,"") | R46: 104855 | S46: <00/01/1900 | V46: 18
G47: aesmaeilzadeh | H47: Esmaeilzadeh | J47: 6 | L47: 6 | N47: =IF(L47>4,1,0) -> 1 | O47: =IF(J47>4,1,0) -> 1 | P47: =IF(OR(ISBLANK(J47),J47<5),G47,"") | S47: 17 | V47: 188
G48: agautier | H48: Gautier | I48: 6 | L48: 6 | N48: =IF(L48>4,1,0) -> 1 | O48: =IF(J48>4,1,0) -> 0 | P48: =IF(OR(ISBLANK(J48),J48<5),G48,"") -> agautier | R48: 104959 | S48: <00/01/1900 | V48: 36
G49: agrizard | H49: Grizard | I49: 5 | J49: 1 | L49: 6 | N49: =IF(L49>4,1,0) -> 1 | O49: =IF(J49>4,1,0) -> 0 | P49: =IF(OR(ISBLANK(J49),J49<5),G49,"") -> agrizard | S49: 11 | V49: 206
G50: agross1 | H50: Gross | J50: 6 | L50: 6 | N50: =IF(L50>4,1,0) -> 1 | O50: =IF(J50>4,1,0) -> 1 | P50: =IF(OR(ISBLANK(J50),J50<5),G50,"") | R50: (vide) | S50: <00/01/1900
G51: aguyduche | H51: Guy-Duché | J51: 6 | L51: 6 | N51: =IF(L51>4,1,0) -> 1 | O51: =IF(J51>4,1,0) -> 1 | P51: =IF(OR(ISBLANK(J51),J51<5),G51,"")
G52: ahuerta | H52: Huerta | J52: 6 | L52: 6 | N52: =IF(L52>4,1,0) -> 1 | O52: =IF(J52>4,1,0) -> 1 | P52: =IF(OR(ISBLANK(J52),J52<5),G52,"")
G53: ajeannot | H53: Jeannot | I53: 1 | J53: 5 | L53: 6 | N53: =IF(L53>4,1,0) -> 1 | O53: =IF(J53>4,1,0) -> 1 | P53: =IF(OR(ISBLANK(J53),J53<5),G53,"")
G54: akerouanton | H54: Kerouanton | J54: 6 | L54: 6 | N54: =IF(L54>4,1,0) -> 1 | O54: =IF(J54>4,1,0) -> 1 | P54: =IF(OR(ISBLANK(J54),J54<5),G54,"")
G55: alhomme | H55: Lhomme | J55: 3 | L55: 3 | N55: =IF(L55>4,1,0) -> 0 | O55: =IF(J55>4,1,0) -> 0 | P55: =IF(OR(ISBLANK(J55),J55<5),G55,"") -> alhomme
G56: alvgalichet | H56: Galichet | J56: 6 | L56: 6 | N56: =IF(L56>4,1,0) -> 1 | O56: =IF(J56>4,1,0) -> 1 | P56: =IF(OR(ISBLANK(J56),J56<5),G56,"")
G57: amansart | H57: Mansart | J57: 6 | L57: 6 | N57: =IF(L57>4,1,0) -> 1 | O57: =IF(J57>4,1,0) -> 1 | P57: =IF(OR(ISBLANK(J57),J57<5),G57,"")
G58: amoen | H58: Moen | J58: 6 | L58: 6 | N58: =IF(L58>4,1,0) -> 1 | O58: =IF(J58>4,1,0) -> 1 | P58: =IF(OR(ISBLANK(J58),J58<5),G58,"")
G59: amoreira1 | H59: Moreira | J59: 6 | L59: 6 | N59: =IF(L59>4,1,0) -> 1 | O59: =IF(J59>4,1,0) -> 1 | P59: =IF(OR(ISBLANK(J59),J59<5),G59,"")
G60: anantois | H60: Nantois | J60: 6 | L60: 6 | N60: =IF(L60>4,1,0) -> 1 | O60: =IF(J60>4,1,0) -> 1 | P60: =IF(OR(ISBLANK(J60),J60<5),G60,"")
G61: aolech | H61: Olech | I61: 6 | L61: 6 | N61: =IF(L61>4,1,0) -> 1 | O61: =IF(J61>4,1,0) -> 0 | P61: =IF(OR(ISBLANK(J61),J61<5),G61,"") -> aolech
G62: apesnel | H62: Pesnel | J62: 6 | L62: 6 | N62: =IF(L62>4,1,0) -> 1 | O62: =IF(J62>4,1,0) -> 1 | P62: =IF(OR(ISBLANK(J62),J62<5),G62,"")
G63: apichard | H63: Pichard | I63: 1 | J63: 5 | L63: 6 | N63: =IF(L63>4,1,0) -> 1 | O63: =IF(J63>4,1,0) -> 1 | P63: =IF(OR(ISBLANK(J63),J63<5),G63,"")
G64: apollier | H64: Pollier | J64: 1 | L64: 1 | N64: =IF(L64>4,1,0) -> 0 | O64: =IF(J64>4,1,0) -> 0 | P64: =IF(OR(ISBLANK(J64),J64<5),G64,"") -> apollier
...

Sheet Brouillon
A1: Etudiants
A2: abomont
A10: agautier
A11: agrizard
A17: alhomme
A23: aolech
A26: apollier
A27: arajaobelina
A30: atorres
A31: bnaji
A34: cdelvalle
A36: cpauvert
... A250: yli2
